 * Serving Flask app 'web_server'
 * Debug mode: on
WARNING: This is a development server. Do not use it in a production deployment. Use a production WSGI server instead.
 * Running on all addresses (0.0.0.0)
 * Running on http://127.0.0.1:5001
 * Running on http://192.168.1.17:5001
Press CTRL+C to quit
 * Restarting with stat
 * Debugger is active!
 * Debugger PIN: 130-399-691
127.0.0.1 - - [15/Oct/2024 01:26:49] "GET /get_products HTTP/1.1" 200 -
127.0.0.1 - - [15/Oct/2024 01:26:52] "GET /get_products HTTP/1.1" 200 -
 * Serving Flask app 'web_server'
 * Debug mode: on
WARNING: This is a development server. Do not use it in a production deployment. Use a production WSGI server instead.
 * Running on all addresses (0.0.0.0)
 * Running on http://127.0.0.1:5001
 * Running on http://192.168.1.17:5001
Press CTRL+C to quit
 * Restarting with stat
 * Debugger is active!
 * Debugger PIN: 130-399-691
127.0.0.1 - - [15/Oct/2024 01:30:35] "GET /get_products HTTP/1.1" 200 -
127.0.0.1 - - [15/Oct/2024 01:30:36] "GET /get_products HTTP/1.1" 200 -
127.0.0.1 - - [15/Oct/2024 01:30:44] "GET /get_products HTTP/1.1" 200 -
127.0.0.1 - - [15/Oct/2024 01:30:45] "GET /get_products HTTP/1.1" 200 -
127.0.0.1 - - [15/Oct/2024 01:31:10] "GET /get_products HTTP/1.1" 200 -
127.0.0.1 - - [15/Oct/2024 01:31:10] "GET /get_products HTTP/1.1" 200 -
 * Serving Flask app 'web_server'
 * Debug mode: on
WARNING: This is a development server. Do not use it in a production deployment. Use a production WSGI server instead.
 * Running on all addresses (0.0.0.0)
 * Running on http://127.0.0.1:5001
 * Running on http://192.168.1.17:5001
Press CTRL+C to quit
 * Restarting with stat
 * Debugger is active!
 * Debugger PIN: 130-399-691
127.0.0.1 - - [15/Oct/2024 01:33:45] "GET /get_products HTTP/1.1" 200 -
127.0.0.1 - - [15/Oct/2024 01:33:49] "GET /get_products HTTP/1.1" 200 -
127.0.0.1 - - [15/Oct/2024 01:33:50] "GET /get_products HTTP/1.1" 200 -
127.0.0.1 - - [15/Oct/2024 01:35:05] "POST /price_prediction HTTP/1.1" 200 -
127.0.0.1 - - [15/Oct/2024 01:35:05] "GET /get_products HTTP/1.1" 200 -
 * Serving Flask app 'web_server'
 * Debug mode: on
WARNING: This is a development server. Do not use it in a production deployment. Use a production WSGI server instead.
 * Running on all addresses (0.0.0.0)
 * Running on http://127.0.0.1:5001
 * Running on http://192.168.12.6:5001
Press CTRL+C to quit
 * Restarting with stat
 * Debugger is active!
 * Debugger PIN: 676-692-317

  You can now view your Streamlit app in your browser.

  Local URL: http://localhost:8501
  Network URL: http://192.168.12.6:8501

2024-10-15 23:46:50.400 Uncaught app exception
Traceback (most recent call last):
  File "/home/osama/DEPI_project_workspace/web_server/.venv/lib/python3.11/site-packages/urllib3/connection.py", line 199, in _new_conn
    sock = connection.create_connection(
           ^^^^^^^^^^^^^^^^^^^^^^^^^^^^^
  File "/home/osama/DEPI_project_workspace/web_server/.venv/lib/python3.11/site-packages/urllib3/util/connection.py", line 85, in create_connection
    raise err
  File "/home/osama/DEPI_project_workspace/web_server/.venv/lib/python3.11/site-packages/urllib3/util/connection.py", line 73, in create_connection
    sock.connect(sa)
ConnectionRefusedError: [Errno 111] Connection refused

The above exception was the direct cause of the following exception:

Traceback (most recent call last):
  File "/home/osama/DEPI_project_workspace/web_server/.venv/lib/python3.11/site-packages/urllib3/connectionpool.py", line 789, in urlopen
    response = self._make_request(
               ^^^^^^^^^^^^^^^^^^^
  File "/home/osama/DEPI_project_workspace/web_server/.venv/lib/python3.11/site-packages/urllib3/connectionpool.py", line 495, in _make_request
    conn.request(
  File "/home/osama/DEPI_project_workspace/web_server/.venv/lib/python3.11/site-packages/urllib3/connection.py", line 441, in request
    self.endheaders()
  File "/usr/lib/python3.11/http/client.py", line 1277, in endheaders
    self._send_output(message_body, encode_chunked=encode_chunked)
  File "/usr/lib/python3.11/http/client.py", line 1037, in _send_output
    self.send(msg)
  File "/usr/lib/python3.11/http/client.py", line 975, in send
    self.connect()
  File "/home/osama/DEPI_project_workspace/web_server/.venv/lib/python3.11/site-packages/urllib3/connection.py", line 279, in connect
    self.sock = self._new_conn()
                ^^^^^^^^^^^^^^^^
  File "/home/osama/DEPI_project_workspace/web_server/.venv/lib/python3.11/site-packages/urllib3/connection.py", line 214, in _new_conn
    raise NewConnectionError(
urllib3.exceptions.NewConnectionError: <urllib3.connection.HTTPConnection object at 0x7f09043ae2d0>: Failed to establish a new connection: [Errno 111] Connection refused

The above exception was the direct cause of the following exception:

Traceback (most recent call last):
  File "/home/osama/DEPI_project_workspace/web_server/.venv/lib/python3.11/site-packages/requests/adapters.py", line 667, in send
    resp = conn.urlopen(
           ^^^^^^^^^^^^^
  File "/home/osama/DEPI_project_workspace/web_server/.venv/lib/python3.11/site-packages/urllib3/connectionpool.py", line 843, in urlopen
    retries = retries.increment(
              ^^^^^^^^^^^^^^^^^^
  File "/home/osama/DEPI_project_workspace/web_server/.venv/lib/python3.11/site-packages/urllib3/util/retry.py", line 519, in increment
    raise MaxRetryError(_pool, url, reason) from reason  # type: ignore[arg-type]
    ^^^^^^^^^^^^^^^^^^^^^^^^^^^^^^^^^^^^^^^^^^^^^^^^^^^
urllib3.exceptions.MaxRetryError: HTTPConnectionPool(host='192.168.12.119', port=5001): Max retries exceeded with url: /get_products (Caused by NewConnectionError('<urllib3.connection.HTTPConnection object at 0x7f09043ae2d0>: Failed to establish a new connection: [Errno 111] Connection refused'))

During handling of the above exception, another exception occurred:

Traceback (most recent call last):
  File "/home/osama/DEPI_project_workspace/web_server/.venv/lib/python3.11/site-packages/streamlit/runtime/scriptrunner/exec_code.py", line 88, in exec_func_with_error_handling
    result = func()
             ^^^^^^
  File "/home/osama/DEPI_project_workspace/web_server/.venv/lib/python3.11/site-packages/streamlit/runtime/scriptrunner/script_runner.py", line 579, in code_to_exec
    exec(code, module.__dict__)
  File "/home/osama/DEPI_project_workspace/web_server/streamlit/home.py", line 42, in <module>
    prediction_form("Price")
  File "/home/osama/DEPI_project_workspace/web_server/streamlit/predictors.py", line 64, in prediction_form
    response = requests.get(f'{PREDICTION_SERVER_URL}/get_products')
               ^^^^^^^^^^^^^^^^^^^^^^^^^^^^^^^^^^^^^^^^^^^^^^^^^^^^^
  File "/home/osama/DEPI_project_workspace/web_server/.venv/lib/python3.11/site-packages/requests/api.py", line 73, in get
    return request("get", url, params=params, **kwargs)
           ^^^^^^^^^^^^^^^^^^^^^^^^^^^^^^^^^^^^^^^^^^^^
  File "/home/osama/DEPI_project_workspace/web_server/.venv/lib/python3.11/site-packages/requests/api.py", line 59, in request
    return session.request(method=method, url=url, **kwargs)
           ^^^^^^^^^^^^^^^^^^^^^^^^^^^^^^^^^^^^^^^^^^^^^^^^^
  File "/home/osama/DEPI_project_workspace/web_server/.venv/lib/python3.11/site-packages/requests/sessions.py", line 589, in request
    resp = self.send(prep, **send_kwargs)
           ^^^^^^^^^^^^^^^^^^^^^^^^^^^^^^
  File "/home/osama/DEPI_project_workspace/web_server/.venv/lib/python3.11/site-packages/requests/sessions.py", line 703, in send
    r = adapter.send(request, **kwargs)
        ^^^^^^^^^^^^^^^^^^^^^^^^^^^^^^^
  File "/home/osama/DEPI_project_workspace/web_server/.venv/lib/python3.11/site-packages/requests/adapters.py", line 700, in send
    raise ConnectionError(e, request=request)
requests.exceptions.ConnectionError: HTTPConnectionPool(host='192.168.12.119', port=5001): Max retries exceeded with url: /get_products (Caused by NewConnectionError('<urllib3.connection.HTTPConnection object at 0x7f09043ae2d0>: Failed to establish a new connection: [Errno 111] Connection refused'))
2024-10-15 23:47:05.759 Uncaught app exception
Traceback (most recent call last):
  File "/home/osama/DEPI_project_workspace/web_server/.venv/lib/python3.11/site-packages/urllib3/connection.py", line 199, in _new_conn
    sock = connection.create_connection(
           ^^^^^^^^^^^^^^^^^^^^^^^^^^^^^
  File "/home/osama/DEPI_project_workspace/web_server/.venv/lib/python3.11/site-packages/urllib3/util/connection.py", line 85, in create_connection
    raise err
  File "/home/osama/DEPI_project_workspace/web_server/.venv/lib/python3.11/site-packages/urllib3/util/connection.py", line 73, in create_connection
    sock.connect(sa)
ConnectionRefusedError: [Errno 111] Connection refused

The above exception was the direct cause of the following exception:

Traceback (most recent call last):
  File "/home/osama/DEPI_project_workspace/web_server/.venv/lib/python3.11/site-packages/urllib3/connectionpool.py", line 789, in urlopen
    response = self._make_request(
               ^^^^^^^^^^^^^^^^^^^
  File "/home/osama/DEPI_project_workspace/web_server/.venv/lib/python3.11/site-packages/urllib3/connectionpool.py", line 495, in _make_request
    conn.request(
  File "/home/osama/DEPI_project_workspace/web_server/.venv/lib/python3.11/site-packages/urllib3/connection.py", line 441, in request
    self.endheaders()
  File "/usr/lib/python3.11/http/client.py", line 1277, in endheaders
    self._send_output(message_body, encode_chunked=encode_chunked)
  File "/usr/lib/python3.11/http/client.py", line 1037, in _send_output
    self.send(msg)
  File "/usr/lib/python3.11/http/client.py", line 975, in send
    self.connect()
  File "/home/osama/DEPI_project_workspace/web_server/.venv/lib/python3.11/site-packages/urllib3/connection.py", line 279, in connect
    self.sock = self._new_conn()
                ^^^^^^^^^^^^^^^^
  File "/home/osama/DEPI_project_workspace/web_server/.venv/lib/python3.11/site-packages/urllib3/connection.py", line 214, in _new_conn
    raise NewConnectionError(
urllib3.exceptions.NewConnectionError: <urllib3.connection.HTTPConnection object at 0x7f090438b810>: Failed to establish a new connection: [Errno 111] Connection refused

The above exception was the direct cause of the following exception:

Traceback (most recent call last):
  File "/home/osama/DEPI_project_workspace/web_server/.venv/lib/python3.11/site-packages/requests/adapters.py", line 667, in send
    resp = conn.urlopen(
           ^^^^^^^^^^^^^
  File "/home/osama/DEPI_project_workspace/web_server/.venv/lib/python3.11/site-packages/urllib3/connectionpool.py", line 843, in urlopen
    retries = retries.increment(
              ^^^^^^^^^^^^^^^^^^
  File "/home/osama/DEPI_project_workspace/web_server/.venv/lib/python3.11/site-packages/urllib3/util/retry.py", line 519, in increment
    raise MaxRetryError(_pool, url, reason) from reason  # type: ignore[arg-type]
    ^^^^^^^^^^^^^^^^^^^^^^^^^^^^^^^^^^^^^^^^^^^^^^^^^^^
urllib3.exceptions.MaxRetryError: HTTPConnectionPool(host='192.168.12.119', port=5001): Max retries exceeded with url: /get_products (Caused by NewConnectionError('<urllib3.connection.HTTPConnection object at 0x7f090438b810>: Failed to establish a new connection: [Errno 111] Connection refused'))

During handling of the above exception, another exception occurred:

Traceback (most recent call last):
  File "/home/osama/DEPI_project_workspace/web_server/.venv/lib/python3.11/site-packages/streamlit/runtime/scriptrunner/exec_code.py", line 88, in exec_func_with_error_handling
    result = func()
             ^^^^^^
  File "/home/osama/DEPI_project_workspace/web_server/.venv/lib/python3.11/site-packages/streamlit/runtime/scriptrunner/script_runner.py", line 579, in code_to_exec
    exec(code, module.__dict__)
  File "/home/osama/DEPI_project_workspace/web_server/streamlit/home.py", line 44, in <module>
    prediction_form("Demand")
  File "/home/osama/DEPI_project_workspace/web_server/streamlit/predictors.py", line 64, in prediction_form
    response = requests.get(f'{PREDICTION_SERVER_URL}/get_products')
               ^^^^^^^^^^^^^^^^^^^^^^^^^^^^^^^^^^^^^^^^^^^^^^^^^^^^^
  File "/home/osama/DEPI_project_workspace/web_server/.venv/lib/python3.11/site-packages/requests/api.py", line 73, in get
    return request("get", url, params=params, **kwargs)
           ^^^^^^^^^^^^^^^^^^^^^^^^^^^^^^^^^^^^^^^^^^^^
  File "/home/osama/DEPI_project_workspace/web_server/.venv/lib/python3.11/site-packages/requests/api.py", line 59, in request
    return session.request(method=method, url=url, **kwargs)
           ^^^^^^^^^^^^^^^^^^^^^^^^^^^^^^^^^^^^^^^^^^^^^^^^^
  File "/home/osama/DEPI_project_workspace/web_server/.venv/lib/python3.11/site-packages/requests/sessions.py", line 589, in request
    resp = self.send(prep, **send_kwargs)
           ^^^^^^^^^^^^^^^^^^^^^^^^^^^^^^
  File "/home/osama/DEPI_project_workspace/web_server/.venv/lib/python3.11/site-packages/requests/sessions.py", line 703, in send
    r = adapter.send(request, **kwargs)
        ^^^^^^^^^^^^^^^^^^^^^^^^^^^^^^^
  File "/home/osama/DEPI_project_workspace/web_server/.venv/lib/python3.11/site-packages/requests/adapters.py", line 700, in send
    raise ConnectionError(e, request=request)
requests.exceptions.ConnectionError: HTTPConnectionPool(host='192.168.12.119', port=5001): Max retries exceeded with url: /get_products (Caused by NewConnectionError('<urllib3.connection.HTTPConnection object at 0x7f090438b810>: Failed to establish a new connection: [Errno 111] Connection refused'))
2024-10-15 23:47:07.216 Uncaught app exception
Traceback (most recent call last):
  File "/home/osama/DEPI_project_workspace/web_server/.venv/lib/python3.11/site-packages/urllib3/connection.py", line 199, in _new_conn
    sock = connection.create_connection(
           ^^^^^^^^^^^^^^^^^^^^^^^^^^^^^
  File "/home/osama/DEPI_project_workspace/web_server/.venv/lib/python3.11/site-packages/urllib3/util/connection.py", line 85, in create_connection
    raise err
  File "/home/osama/DEPI_project_workspace/web_server/.venv/lib/python3.11/site-packages/urllib3/util/connection.py", line 73, in create_connection
    sock.connect(sa)
ConnectionRefusedError: [Errno 111] Connection refused

The above exception was the direct cause of the following exception:

Traceback (most recent call last):
  File "/home/osama/DEPI_project_workspace/web_server/.venv/lib/python3.11/site-packages/urllib3/connectionpool.py", line 789, in urlopen
    response = self._make_request(
               ^^^^^^^^^^^^^^^^^^^
  File "/home/osama/DEPI_project_workspace/web_server/.venv/lib/python3.11/site-packages/urllib3/connectionpool.py", line 495, in _make_request
    conn.request(
  File "/home/osama/DEPI_project_workspace/web_server/.venv/lib/python3.11/site-packages/urllib3/connection.py", line 441, in request
    self.endheaders()
  File "/usr/lib/python3.11/http/client.py", line 1277, in endheaders
    self._send_output(message_body, encode_chunked=encode_chunked)
  File "/usr/lib/python3.11/http/client.py", line 1037, in _send_output
    self.send(msg)
  File "/usr/lib/python3.11/http/client.py", line 975, in send
    self.connect()
  File "/home/osama/DEPI_project_workspace/web_server/.venv/lib/python3.11/site-packages/urllib3/connection.py", line 279, in connect
    self.sock = self._new_conn()
                ^^^^^^^^^^^^^^^^
  File "/home/osama/DEPI_project_workspace/web_server/.venv/lib/python3.11/site-packages/urllib3/connection.py", line 214, in _new_conn
    raise NewConnectionError(
urllib3.exceptions.NewConnectionError: <urllib3.connection.HTTPConnection object at 0x7f09043b4690>: Failed to establish a new connection: [Errno 111] Connection refused

The above exception was the direct cause of the following exception:

Traceback (most recent call last):
  File "/home/osama/DEPI_project_workspace/web_server/.venv/lib/python3.11/site-packages/requests/adapters.py", line 667, in send
    resp = conn.urlopen(
           ^^^^^^^^^^^^^
  File "/home/osama/DEPI_project_workspace/web_server/.venv/lib/python3.11/site-packages/urllib3/connectionpool.py", line 843, in urlopen
    retries = retries.increment(
              ^^^^^^^^^^^^^^^^^^
  File "/home/osama/DEPI_project_workspace/web_server/.venv/lib/python3.11/site-packages/urllib3/util/retry.py", line 519, in increment
    raise MaxRetryError(_pool, url, reason) from reason  # type: ignore[arg-type]
    ^^^^^^^^^^^^^^^^^^^^^^^^^^^^^^^^^^^^^^^^^^^^^^^^^^^
urllib3.exceptions.MaxRetryError: HTTPConnectionPool(host='192.168.12.119', port=5001): Max retries exceeded with url: /get_products (Caused by NewConnectionError('<urllib3.connection.HTTPConnection object at 0x7f09043b4690>: Failed to establish a new connection: [Errno 111] Connection refused'))

During handling of the above exception, another exception occurred:

Traceback (most recent call last):
  File "/home/osama/DEPI_project_workspace/web_server/.venv/lib/python3.11/site-packages/streamlit/runtime/scriptrunner/exec_code.py", line 88, in exec_func_with_error_handling
    result = func()
             ^^^^^^
  File "/home/osama/DEPI_project_workspace/web_server/.venv/lib/python3.11/site-packages/streamlit/runtime/scriptrunner/script_runner.py", line 579, in code_to_exec
    exec(code, module.__dict__)
  File "/home/osama/DEPI_project_workspace/web_server/streamlit/home.py", line 42, in <module>
    prediction_form("Price")
  File "/home/osama/DEPI_project_workspace/web_server/streamlit/predictors.py", line 64, in prediction_form
    response = requests.get(f'{PREDICTION_SERVER_URL}/get_products')
               ^^^^^^^^^^^^^^^^^^^^^^^^^^^^^^^^^^^^^^^^^^^^^^^^^^^^^
  File "/home/osama/DEPI_project_workspace/web_server/.venv/lib/python3.11/site-packages/requests/api.py", line 73, in get
    return request("get", url, params=params, **kwargs)
           ^^^^^^^^^^^^^^^^^^^^^^^^^^^^^^^^^^^^^^^^^^^^
  File "/home/osama/DEPI_project_workspace/web_server/.venv/lib/python3.11/site-packages/requests/api.py", line 59, in request
    return session.request(method=method, url=url, **kwargs)
           ^^^^^^^^^^^^^^^^^^^^^^^^^^^^^^^^^^^^^^^^^^^^^^^^^
  File "/home/osama/DEPI_project_workspace/web_server/.venv/lib/python3.11/site-packages/requests/sessions.py", line 589, in request
    resp = self.send(prep, **send_kwargs)
           ^^^^^^^^^^^^^^^^^^^^^^^^^^^^^^
  File "/home/osama/DEPI_project_workspace/web_server/.venv/lib/python3.11/site-packages/requests/sessions.py", line 703, in send
    r = adapter.send(request, **kwargs)
        ^^^^^^^^^^^^^^^^^^^^^^^^^^^^^^^
  File "/home/osama/DEPI_project_workspace/web_server/.venv/lib/python3.11/site-packages/requests/adapters.py", line 700, in send
    raise ConnectionError(e, request=request)
requests.exceptions.ConnectionError: HTTPConnectionPool(host='192.168.12.119', port=5001): Max retries exceeded with url: /get_products (Caused by NewConnectionError('<urllib3.connection.HTTPConnection object at 0x7f09043b4690>: Failed to establish a new connection: [Errno 111] Connection refused'))
 * Detected change in '/home/osama/DEPI_project_workspace/web_server/streamlit/predictors.py', reloading
 * Restarting with stat
 * Debugger is active!
 * Debugger PIN: 676-692-317
 * Detected change in '/home/osama/DEPI_project_workspace/web_server/streamlit/predictors.py', reloading
 * Restarting with stat
 * Debugger is active!
 * Debugger PIN: 676-692-317
 * Detected change in '/home/osama/DEPI_project_workspace/web_server/streamlit/predictors.py', reloading
 * Restarting with stat
 * Debugger is active!
 * Debugger PIN: 676-692-317
ad_text:  <h1>Get Organized with Ease! </h1> 
<h2>4 Tier Stackable Storage Bins with Wheels! </h2>
Tired of clutter?  These stackable storage bins with wheels are the perfect solution for organizing your home, office, or dorm. They are easy to assemble, stackable, and portable, making them the ideal storage solution for any space.  
<br>
<br>
 **Features:**
* Easy Assembly 
* Good Storage Space 
* Stackable 
* Portable 
* Affordable 
* Good Value
* Easy to Clean 
<br> 
<br>
 **Click here to learn more and order today!** 
<br>
<a href="https://www.amazon.com/Tier-Collapsible-Storage-Bins-Wheels/dp/B0CGZ9ZK4Z/ref=sr_1_2?_encoding=UTF8&content-id=amzn1.sym.83009b1f-702c-4be7-814b-0240b8f687d2&dib=eyJ2IjoiMSJ9.JGSwFqUk66qqxXhBhvKvJny_I5APdPmY6sk3dWiccnC5uV4Ch3cBFGHfTgFrJ42la2sgUsECpT-IBTKshsP8gT5I_OMPqE831HYeEUIvcAJbarkEHa-_dC2YzPxUJtrMzZA58qsGcqvqe-L6UnUtEovSPe_ghVLwERrvUGBcAqPCAW0drM69cx5zX7V5XhjYw19_7OLzDVFpAZJFZbc2e1P0yPsQfeyPsJwBqmIm4X7wHzSOIvvr5YtoPAe1O7twOKhs8HljljxLiPjUe8Yu8EoKpf0LBz63otUbjQ7w3no.y6ntQsqm8KY7iWulR20gk5wm3HmdPEYAgzMVCWBrvq8&dib_tag=se&keywords=home+storage&pd_rd_r=90866484-14ee-4dbf-ba8a-df9c194ec007&pd_rd_w=A5rfu&pd_rd_wg=E4Ya9&pf_rd_p=83009b1f-702c-4be7-814b-0240b8f687d2&pf_rd_r=3JDYR49R49G1QECG61RW&qid=1728808978&sr=8-2">Get Yours Now! </a> 
<br> 
<br>
**#organizedhome #storagebins #homeorganization #easyassembly #portable** 

  Stopping...

  You can now view your Streamlit app in your browser.

  Local URL: http://localhost:8501
  Network URL: http://192.168.12.6:8501

127.0.0.1 - - [15/Oct/2024 23:53:21] "GET /get_products HTTP/1.1" 200 -
127.0.0.1 - - [15/Oct/2024 23:53:29] "GET /get_products HTTP/1.1" 200 -
127.0.0.1 - - [15/Oct/2024 23:54:03] "GET /get_products HTTP/1.1" 200 -
127.0.0.1 - - [15/Oct/2024 23:54:07] "GET /get_products HTTP/1.1" 200 -
127.0.0.1 - - [15/Oct/2024 23:54:08] "GET /get_products HTTP/1.1" 200 -
127.0.0.1 - - [15/Oct/2024 23:55:09] "GET /get_products HTTP/1.1" 200 -
127.0.0.1 - - [15/Oct/2024 23:55:30] "GET /get_products HTTP/1.1" 200 -
127.0.0.1 - - [15/Oct/2024 23:55:32] "GET /get_products HTTP/1.1" 200 -
127.0.0.1 - - [15/Oct/2024 23:55:37] "GET /get_products HTTP/1.1" 200 -
127.0.0.1 - - [15/Oct/2024 23:55:39] "GET /get_products HTTP/1.1" 200 -
 * Detected change in '/home/osama/DEPI_project_workspace/web_server/streamlit/predictors.py', reloading
 * Restarting with stat
 * Debugger is active!
 * Debugger PIN: 676-692-317
  Stopping...

  You can now view your Streamlit app in your browser.

  Local URL: http://localhost:8501
  Network URL: http://192.168.12.6:8501

127.0.0.1 - - [15/Oct/2024 23:58:51] "GET /get_products HTTP/1.1" 200 -
127.0.0.1 - - [15/Oct/2024 23:58:53] "GET /get_products HTTP/1.1" 200 -
127.0.0.1 - - [15/Oct/2024 23:58:58] "GET /get_products HTTP/1.1" 200 -
127.0.0.1 - - [15/Oct/2024 23:59:14] "GET /get_products HTTP/1.1" 200 -
127.0.0.1 - - [15/Oct/2024 23:59:15] "GET /get_products HTTP/1.1" 200 -
127.0.0.1 - - [15/Oct/2024 23:59:20] "GET /get_products HTTP/1.1" 200 -
127.0.0.1 - - [15/Oct/2024 23:59:24] "GET /get_products HTTP/1.1" 200 -
127.0.0.1 - - [15/Oct/2024 23:59:25] "GET /get_products HTTP/1.1" 200 -
127.0.0.1 - - [15/Oct/2024 23:59:30] "GET /get_products HTTP/1.1" 200 -
  Stopping...
